Workbook
Name AddLoans: '1-StartingPoint'!$D$36
Name Advertising: '1-StartingPoint'!$C$26
Name Annual_Interest_Rate: #REF!
Name Beg_Bal: #REF!
Name Buildings: '1-StartingPoint'!$C$10
Name Category1: '3a-SalesForecastYear1'!$B$9
Name Category1_Annual_Sales: '3a-SalesForecastYear1'!$O$19
Name Category1_SalesPrice: '3a-SalesForecastYear1'!#REF!
Name Category2: '3a-SalesForecastYear1'!$B$10
Name Category2_Annual_Sales: '3a-SalesForecastYear1'!$O$25
Name Category2_SalesPrice: '3a-SalesForecastYear1'!#REF!
Name Category3: '3a-SalesForecastYear1'!$B$11
Name Category3_Annual_Sales: '3a-SalesForecastYear1'!$O$31
Name Category3_SalesPrice: '3a-SalesForecastYear1'!#REF!
Name Category4: '3a-SalesForecastYear1'!$B$12
Name Category4_Annual_Sales: '3a-SalesForecastYear1'!$O$37
Name Category4_SalesPrice: '3a-SalesForecastYear1'!#REF!
Name Category5: '3a-SalesForecastYear1'!$B$13
Name Category5_Annual_Sales: '3a-SalesForecastYear1'!$O$43
Name Category5_SalesPrice: '3a-SalesForecastYear1'!#REF!
Name Category6: '3a-SalesForecastYear1'!$B$14
Name Category6_Annual_Sales: '3a-SalesForecastYear1'!$O$49
Name Category6_SalesPrice: '3a-SalesForecastYear1'!#REF!
Name Catergory6: '3a-SalesForecastYear1'!$B$14
Name CCDebt: '1-StartingPoint'!$D$39
Name COGS_Annual_Total: '3a-SalesForecastYear1'!$O$54
Name CommLoan: '1-StartingPoint'!$D$37
Name CommMortgage: '1-StartingPoint'!$D$38
Name ContingencyCash: '1-StartingPoint'!#REF!
Name Equipment: '1-StartingPoint'!$C$12
Name Extra_Pay: #REF!
Name Furniture: '1-StartingPoint'!$C$13
Name Growth_Rate_Yr2: '3b-SalesForecastYrs1-3'!$C$7
Name Growth_Rate_Yr3: '3b-SalesForecastYrs1-3'!$C$8
Name Info_Entered: #REF!
Name Int: #REF!
Name InterestRate_ShortTerm: #REF!
Name Inventory: '1-StartingPoint'!$C$21
Name Land: '1-StartingPoint'!$C$9
Name Last_Row: IF(Values_Entered,Header_Row+Number_of_Payments,Header_Row)
Name LeaseImprovements: '1-StartingPoint'!$C$11
Name LegalAcctFees: '1-StartingPoint'!$C$22
Name Licenses: '1-StartingPoint'!$C$27
Name Loan_Amount: #REF!
Name Loan_Term_Years: #REF!
Name LoanAmount_ShortTerm: #REF!
Name LoanTermYears_ShortTerm: #REF!
Name Margin_Annual_Total: '3a-SalesForecastYear1'!$O$55
Name Misc_Expenses: '5a-OpExYear1'!$O$19
Name Monthly_Payment_LongTerm: #REF!
Name NetIncomeY1: '7b-IncomeStatementYrs1-3'!$C$59
Name NetIncomeY2: '7b-IncomeStatementYrs1-3'!$E$59
Name NetIncomeY3: '7b-IncomeStatementYrs1-3'!$G$59
Name Number_of_Payments: MATCH(0.01,End_Bal,-1)+1
Name OfficeSupplies_Expenses: '5a-OpExYear1'!$O$20
Name Other_Expenses: '5a-OpExYear1'!$O$21
Name OtherBankDebt: '1-StartingPoint'!$D$41
Name OtherFixedAssets: '1-StartingPoint'!$C$15
Name OtherStartUp: '1-StartingPoint'!$C$28
Name OutsideInvest: '1-StartingPoint'!$D$35

Sheet Directions
B7: Step 1 - Enter info about your company in yellow shaded boxes below.
C9: Preparer Name | D9: Company Name | E9: Starting Month | F9: Starting Year
B12: Step 2 - Read the following instructions
C36: =IF(ISBLANK(E10),-10000,MONTH(DATEVALUE(E10&" 1")))
B38: =IF(Directions!$C$36>0,CHOOSE(Directions!$C$36,"January","February","March","April","May","June","July","August","September","October","November","December"),"Month 1") | C38: =IF(Directions!$C$36+1>12,CHOOSE(Directions!$C$36+1-12,"January","February","March","April","May","June","July","August","September","October","November","December"),IF(Directions!$C$36<0,"Month 2",(CHOOSE(Directions!$C$36+1,"January","February","March","April","May","June","July","August","September","October","November","December")))) | D38: =IF(Directions!$C$36+2>12,CHOOSE(Directions!$C$36+2-12,"January","February","March","April","May","June","July","August","September","October","November","December"),IF(Directions!$C$36<0,"Month 3",CHOOSE(Directions!$C$36+2,"January","February","March","April","May","June","July","August","September","October","November","December"))) | E38: =IF(Directions!$C$36+3>12,CHOOSE(Directions!$C$36+3-12,"January","February","March","April","May","June","July","August","September","October","November","December"),IF(Directions!$C$36<0,"Month 4",CHOOSE(Directions!$C$36+3,"January","February","March","April","May","June","July","August","September","October","November","December"))) | F38: =IF(Directions!$C$36+4>12,CHOOSE(Directions!$C$36+4-12,"January","February","March","April","May","June","July","August","September","October","November","December"),IF(Directions!$C$36<0,"Month 5",CHOOSE(Directions!$C$36+4,"January","February","March","April","May","June","July","August","September","October","November","December"))) | G38: =IF(Directions!$C$36+5>12,CHOOSE(Directions!$C$36+5-12,"January","February","March","April","May","June","July","August","September","October","November","December"),IF(Directions!$C$36<0,"Month 6",CHOOSE(Directions!$C$36+5,"January","February","March","April","May","June","July","August","September","October","November","December"))) | H38: =IF(Directions!$C$36+6>12,CHOOSE(Directions!$C$36+6-12,"January","February","March","April","May","June","July","August","September","October","November","December"),IF(Directions!$C$36<0,"Month 7",CHOOSE(Directions!$C$36+6,"January","February","March","April","May","June","July","August","September","October","November","December"))) | I38: =IF(Directions!$C$36+7>12,CHOOSE(Directions!$C$36+7-12,"January","February","March","April","May","June","July","August","September","October","November","December"),IF(Directions!$C$36<0,"Month 8",CHOOSE(Directions!$C$36+7,"January","February","March","April","May","June","July","August","September","October","November","December"))) | J38: =IF(Directions!$C$36+8>12,CHOOSE(Directions!$C$36+8-12,"January","February","March","April","May","June","July","August","September","October","November","December"),IF(Directions!$C$36<0,"Month 9",CHOOSE(Directions!$C$36+8,"January","February","March","April","May","June","July","August","September","October","November","December"))) | K38: =IF(Directions!$C$36+9>12,CHOOSE(Directions!$C$36+9-12,"January","February","March","April","May","June","July","August","September","October","November","December"),IF(Directions!$C$36<0,"Month 10",CHOOSE(Directions!$C$36+9,"January","February","March","April","May","June","July","August","September","October","November","December"))) | L38: =IF(Directions!$C$36+10>12,CHOOSE(Directions!$C$36+10-12,"January","February","March","April","May","June","July","August","September","October","November","December"),IF(Directions!$C$36<0,"Month 11",CHOOSE(Directions!$C$36+10,"January","February","March","April","May","June","July","August","September","October","November","December"))) | M38: =IF(Directions!$C$36+11>12,CHOOSE(Directions!$C$36+11-12,"January","February","March","April","May","June","July","August","September","October","November","December"),IF(Directions!$C$36<0,"Month 12",CHOOSE(Directions!$C$36+11,"January","February","March","April","May","June","July","August","September","October","November","December")))

Sheet 1-StartingPoint
B2: Start-up Expenses Year 1 (Starting Balance Sheet)
B4: Grant | C4: Amber's Angels
B5: =IF(ISBLANK(Directions!C10), "Owner", Directions!C10) | C5: =IF(ISBLANK(Directions!D10), "Company 1", Directions!D10)
B7: Fixed Assets | C7: Amount | D7: Depreciation (years) | E7: Notes
B9: Real Estate-Land | D9: Not Depreciated
B10: Real Estate-Buildings | D10: 20
B11: Leasehold Improvements | C11: 2500 | D11: 7
B12: Equipment | D12: 7
B13: Furniture and Fixtures | D13: 5
B14: Vehicles | D14: 5
B15: Other | D15: 5
B16: Total Fixed Assets | C16: =SUM(C9:C15)
B18: Operating Capital | C18: Amount | D18: Notes
B19: Pre-Opening Salaries and Wages
B20: Prepaid Insurance Premiums
B21: Inventory | C21: 400
B22: Legal and Accounting Fees
B23: Rent Deposits
B24: Utility Deposits
B25: Supplies
B26: Advertising and Promotions | C26: 1200
B27: Licenses
B28: Other Initial Start-Up Costs
B29: Working Capital (Cash On Hand)
B30: Total Operating Capital | C30: =SUM(C19:C29)
B31: Total Required Funds | C31: =C16+C30
B33: Sources of Funding | C33: Percentage | D33: Totals | E33: Loan Rate | F33: Term in Months | G33: Monthly Payments | H33: Notes
B34: Owner's Equity | C34: =IF($C$31=0,0,D34/$C$31)
B35: Outside Investors | C35: =IF($C$31=0,0,D35/$C$31)
B36: Additional Loans or Debt
B37: Commercial Loan | C37: =IF($C$31=0,0,D37/$C$31) | E37: 0.09 | F37: 84 | G37: =PMT(E37/12,F37,-D37)
B38: Commercial Mortgage | C38: =IF($C$31=0,0,D38/$C$31) | E38: 0.09 | F38: 240 | G38: =PMT(E38/12,F38,-D38) | J38: See Loan Amortization & Depreciation Schedule
B39: Credit Card Debt | C39: =IF($C$31=0,0,D39/$C$31) | E39: 0.07 | F39: 60 | G39: =PMT(E39/12,F39,-D39)
B40: Vehicle Loans | C40: =IF($C$31=0,0,D40/$C$31) | E40: 0.06 | F40: 48 | G40: =PMT(E40/12,F40,-D40)
B41: Other Bank Debt | C41: =IF($C$31=0,0,D41/$C$31) | E41: 0.05 | F41: 36 | G41: =PMT(E41/12,F41,-D41)
B42: Total Sources of Funding | C42: =IF($C$31=0,0,D42/$C$31) | D42: =SUM(D34:D41) | E42: Cell D 42 must equal cell C31 | G42: =SUM(G37:G41)
B43: Total Funding Needed | D43: =C31-D42 | E43: =IF(D43>0,"You require more funding (Not Balanced)",IF(D43<0,"Your funding exceeds your needs (Not Balanced)","You are fully funded (Balanced)"))
B46: Existing Businesses ONLY -- Calculating Cash on Hand
B47: Cash | C47: 0
B48: + Accounts Receivable | C48: 0
...

Sheet 2a-PayrollYear1
B2: Payroll Year 1
B4: Prepared By: | C4: Company Name:
B5: =IF(ISBLANK(Directions!C10), "Owner", Directions!C10) | C5: =IF(ISBLANK(Directions!D10), "Company 1", Directions!D10)
A7: Employee Types | B7: Number of Owners /Employees | C7: Average Hourly Pay (to 2 decimal places, ex. $15.23) | D7: Estimated Hrs./Week (per person) | E7: Estimated Pay/Month (Total) | F7: =Directions!B38 | G7: =Directions!C38 | H7: =Directions!D38 | I7: =Directions!E38 | J7: =Directions!F38 | K7: =Directions!G38 | L7: =Directions!H38 | M7: =Directions!I38 | ... Q7: =Directions!M38 | R7: Annual Totals
A8: Owner(s) | E8: =(C8*D8*B8)*52/12 | F8: =E8 | G8: =F8 | H8: =G8 | I8: =H8 | J8: =I8 | K8: =J8 | L8: =K8 | M8: =L8 | ... Q8: =P8 | R8: =SUM(F8:Q8)
A9: Full-Time Employees | E9: =(C9*D9*B9)*52/12 | F9: =E9 | G9: =F9 | H9: =G9 | I9: =H9 | J9: =I9 | K9: =J9 | L9: =K9 | M9: =L9 | ... Q9: =P9 | R9: =SUM(F9:Q9)
A10: Part-Time Employees | E10: =(C10*D10*B10)*52/12 | F10: =E10 | G10: =F10 | H10: =G10 | I10: =H10 | J10: =I10 | K10: =J10 | L10: =K10 | M10: =L10 | ... Q10: =P10 | R10: =SUM(F10:Q10)
A11: Independent Contractors | E11: =(C11*D11*B11)*52/12 | F11: =E11 | G11: =F11 | H11: =G11 | I11: =H11 | J11: =I11 | K11: =J11 | L11: =K11 | M11: =L11 | ... Q11: =P11 | R11: =SUM(F11:Q11)
A12: Total Salaries and Wages | B12: =SUM(B8:B11) | C12: =SUM(C8:C11) | D12: =SUM(D8:D11) | E12: =SUM(E8:E11) | F12: =SUM(F8:F11) | G12: =SUM(G8:G11) | H12: =SUM(H8:H11) | I12: =SUM(I8:I11) | ... R12: =SUM(R8:R11)
A14: Payroll Taxes and Benefits | B14: Wage Base Limit | C14: Percentage of Salary/Wage | E14: Estimated Taxes & Benefits/Month (Total) | F14: ='3a-SalesForecastYear1'!C16 | G14: ='3a-SalesForecastYear1'!D16 | H14: ='3a-SalesForecastYear1'!E16 | I14: ='3a-SalesForecastYear1'!F16 | J14: ='3a-SalesForecastYear1'!G16 | K14: ='3a-SalesForecastYear1'!H16 | L14: ='3a-SalesForecastYear1'!I16 | M14: ='3a-SalesForecastYear1'!J16 | ... R14: ='3a-SalesForecastYear1'!O16
A15: Social Security | B15: 137700 | C15: 0.062 | E15: =(E$8+E$9+E$10)*$C$15 | F15: =(F$8+F$9+F$10)*$C$15 | G15: =(G$8+G$9+G$10)*$C$15 | H15: =(H$8+H$9+H$10)*$C$15 | I15: =(I$8+I$9+I$10)*$C$15 | J15: =(J$8+J$9+J$10)*$C$15 | K15: =(K$8+K$9+K$10)*$C$15 | L15: =(L$8+L$9+L$10)*$C$15 | ... Q15: =(Q$8+Q$9+Q$10)*$C$15 | R15: =SUM(F15:Q15)
A16: Medicare | B16: -- | C16: 0.0145 | E16: =(E$8+E$9+E$10)*$C$16 | F16: =(F$8+F$9+F$10)*$C$16 | G16: =(G$8+G$9+G$10)*$C$16 | H16: =(H$8+H$9+H$10)*$C$16 | I16: =(I$8+I$9+I$10)*$C$16 | J16: =(J$8+J$9+J$10)*$C$16 | K16: =(K$8+K$9+K$10)*$C$16 | L16: =(L$8+L$9+L$10)*$C$16 | ... Q16: =(Q$8+Q$9+Q$10)*$C$16 | R16: =SUM(F16:Q16)
A17: Federal Unemployment Tax (FUTA) | B17: 7000 | C17: 0.006 | E17: =+$B$12*B17*C17/12 | F17: =E17 | G17: =F17 | H17: =G17 | I17: =H17 | J17: =I17 | K17: =J17 | L17: =K17 | M17: =L17 | ... Q17: =P17 | R17: =SUM(F17:Q17)
A18: State Unemployment Tax (SUTA) | B18: 7000 | C18: 0.0345 | E18: =+$B$12*B18*C18/12 | F18: =E18 | G18: =F18 | H18: =G18 | I18: =H18 | J18: =I18 | K18: =J18 | L18: =K18 | M18: =L18 | ... Q18: =P18 | R18: =SUM(F18:Q18)
A19: Employee Pension Programs | B19: -- | C19: 0 | E19: =($E$8+$E$9+$E$10)*C19 | F19: =E19 | G19: =F19 | H19: =G19 | I19: =H19 | J19: =I19 | K19: =J19 | L19: =K19 | M19: =L19 | ... Q19: =P19 | R19: =SUM(F19:Q19)
A20: Worker's Compensation | B20: -- | C20: 0 | E20: =($E$8+$E$9+$E$10)*C20 | F20: =E20 | G20: =F20 | H20: =G20 | I20: =H20 | J20: =I20 | K20: =J20 | L20: =K20 | M20: =L20 | ... Q20: =P20 | R20: =SUM(F20:Q20)
A21: Employee Health Insurance | B21: -- | C21: 0 | E21: =($E$8+$E$9+$E$10)*C21 | F21: =E21 | G21: =F21 | H21: =G21 | I21: =H21 | J21: =I21 | K21: =J21 | L21: =K21 | M21: =L21 | ... Q21: =P21 | R21: =SUM(F21:Q21)
A22: Other Employee Benefit Programs | B22: -- | C22: 0 | E22: =($E$8+$E$9+$E$10)*C22 | F22: =E22 | G22: =F22 | H22: =G22 | I22: =H22 | J22: =I22 | K22: =J22 | L22: =K22 | M22: =L22 | ... Q22: =P22 | R22: =SUM(F22:Q22)
A23: Total Payroll Taxes and Benefits | C23: =SUM(C15:C22) | E23: =SUM(E15:E22) | F23: =SUM(F15:F22) | G23: =SUM(G15:G22) | H23: =SUM(H15:H22) | I23: =SUM(I15:I22) | J23: =SUM(J15:J22) | K23: =SUM(K15:K22) | L23: =SUM(L15:L22) | ... R23: =SUM(R15:R22)
A25: Total Salaries and Related Expenses | E25: =E12+E23 | F25: =F12+F23 | G25: =G12+G23 | H25: =H12+H23 | I25: =I12+I23 | J25: =J12+J23 | K25: =K12+K23 | L25: =L12+L23 | ... R25: =R12+R23

Sheet 2b-PayrollYrs1-3
B2: Payroll Years 1-3
B4: Prepared By: | C4: Company Name:
B5: =IF(ISBLANK(Directions!C10), "Owner", Directions!C10) | C5: =IF(ISBLANK(Directions!D10), "Company 1", Directions!D10)
B8: Employee Types | C8: Year 1 Totals | D8: Growth Rate 1 to 2 | E8: =IF(Directions!G7>0,Directions!G7+1,"Second Year") | F8: Growth Rate 2 to 3 | G8: =IF(Directions!G7>0,Directions!G7+2,"Third Year")
B9: Owner(s) | C9: ='2a-PayrollYear1'!R8 | D9: 0.2 | E9: =C9*D9+C9 | F9: 0.3 | G9: =E9*F9+E9
B10: Full-Time Employees | C10: ='2a-PayrollYear1'!R9 | D10: 0.2 | E10: =C10*D10+C10 | F10: 0.3 | G10: =E10*F10+E10
B11: Part-Time Employees | C11: ='2a-PayrollYear1'!R10 | D11: 0.1 | E11: =C11*D11+C11 | F11: 0.3 | G11: =E11*F11+E11
B12: Independent Contractors | C12: ='2a-PayrollYear1'!R11 | D12: 0.03 | E12: =C12*D12+C12 | F12: 0.03 | G12: =E12*F12+E12
B13: Total Salaries and Wages | C13: =SUM(C9:C12) | E13: =SUM(E9:E12) | G13: =SUM(G9:G12)
B15: Payroll Taxes and Benefits
B16: Social Security | C16: ='2a-PayrollYear1'!R15 | D16: 0.2 | E16: =C16*D16+C16 | F16: 0.3 | G16: =E16*F16+E16
B17: Medicare | C17: ='2a-PayrollYear1'!R16 | D17: 0.2 | E17: =C17*D17+C17 | F17: 0.3 | G17: =E17*F17+E17
B18: Federal Unemployment Tax (FUTA) | C18: ='2a-PayrollYear1'!R17 | D18: 0.2 | E18: =C18*D18+C18 | F18: 0.3 | G18: =E18*F18+E18
B19: State Unemployment Tax (SUTA) | C19: ='2a-PayrollYear1'!R18 | D19: 0.2 | E19: =C19*D19+C19 | F19: 0.3 | G19: =E19*F19+E19
B20: Employee Pension Programs | C20: ='2a-PayrollYear1'!R19 | D20: 0 | E20: =C20*D20+C20 | F20: 0 | G20: =E20*F20+E20
B21: Worker's Compensation | C21: ='2a-PayrollYear1'!R20 | D21: 0.03 | E21: =C21*D21+C21 | F21: 0.03 | G21: =E21*F21+E21
B22: Employee Health Insurance | C22: ='2a-PayrollYear1'!R21 | D22: 0.03 | E22: =C22*D22+C22 | F22: 0.03 | G22: =E22*F22+E22
B23: Other Employee Benefit Programs | C23: ='2a-PayrollYear1'!R22 | D23: 0.1 | E23: =C23*D23+C23 | F23: 0.1 | G23: =E23*F23+E23
B24: Total Payroll Taxes and Benefits | C24: =SUM(C16:C23) | E24: =SUM(E16:E23) | G24: =SUM(G16:G23)
B26: Total Salaries and Related Expenses | C26: =SUM(C13+C24) | E26: =SUM(E13+E24) | G26: =SUM(G13+G24)

Sheet 3a-SalesForecastYear1
B2: Sales Forecast Year 1 Q1 | D2: Q2 | E2: Q3 | F2: Q4
B3: Monthly Growth Rate by Qtr Yr1 | C3: 0.1 | D3: 0.06 | E3: 0.04 | F3: 0.03
B4: Prepared By: | C4: Company Name:
B5: =IF(ISBLANK(Directions!C10), "Owner", Directions!C10) | C5: =IF(ISBLANK(Directions!D10), "Company 1", Directions!D10)
B7: Complete This Chart First:
B8: Product Lines | C8: Units | D8: Sales Price Per Unit | E8: COGS Per Unit | F8: Margin Per Unit
F9: =D9-E9
F10: =D10-E10
F11: =D11-E11
F12: =D12-E12
F13: =D13-E13
F14: =D14-E14
B16: Product Lines | C16: ='2a-PayrollYear1'!F7 | D16: ='2a-PayrollYear1'!G7 | E16: ='2a-PayrollYear1'!H7 | F16: ='2a-PayrollYear1'!I7 | G16: ='2a-PayrollYear1'!J7 | H16: ='2a-PayrollYear1'!K7 | I16: ='2a-PayrollYear1'!L7 | J16: ='2a-PayrollYear1'!M7 | ... N16: ='2a-PayrollYear1'!Q7 | O16: Annual Totals | P16: Category Breakdown | Q16: Category / Total
B17: =IF(ISBLANK(B9), "Product 1", B9)
B18: =IF(ISBLANK(C9), "Units Sold", Unit1& " Sold") | D18: =C18+C18*$C$3 | E18: =D18+D18*$C$3 | F18: =E18+E18*$D$3 | G18: =F18+F18*$D$3 | H18: =G18+G18*$D$3 | I18: =H18+H18*$E$3 | J18: =I18+I18*$E$3 | K18: =J18+J18*$E$3 | L18: =K18+K18*$F$3 | M18: =L18+L18*$F$3 | N18: =M18+M18*$F$3 | O18: =SUM(C18:N18) | Q18: =IF($O$52=0,0,O18/$O$52)
B19: Total Sales | C19: =$D$9*C18 | D19: =$D$9*D18 | E19: =$D$9*E18 | F19: =$D$9*F18 | G19: =$D$9*G18 | H19: =$D$9*H18 | I19: =$D$9*I18 | J19: =$D$9*J18 | ... N19: =$D$9*N18 | O19: =SUM(C19:N19) | P19: =(P20+P21) | Q19: =IF($O$53=0,0,O19/$O$53)
B20: Total COGS | C20: =$E$9*C18 | D20: =$E$9*D18 | E20: =$E$9*E18 | F20: =$E$9*F18 | G20: =$E$9*G18 | H20: =$E$9*H18 | I20: =$E$9*I18 | J20: =$E$9*J18 | ... N20: =$E$9*N18 | O20: =SUM(C20:N20) | P20: =IF(O19=0,0,O20/O19) | Q20: =IF($O$54=0,0,O20/$O$54)
B21: Total Margin | C21: =C19-C20 | D21: =D19-D20 | E21: =E19-E20 | F21: =F19-F20 | G21: =G19-G20 | H21: =H19-H20 | I21: =I19-I20 | J21: =J19-J20 | ... N21: =N19-N20 | O21: =SUM(C21:N21) | P21: =IF(O19=0,0,O21/O19) | Q21: =IF($O$55=0,0,O21/$O$55)
B23: =IF(ISBLANK(B10), "Product 2", B10)
B24: =IF(ISBLANK(C10), "Units Sold", Unit2& " Sold") | D24: =C24+C24*$C$3 | E24: =D24+D24*$C$3 | F24: =E24+E24*$D$3 | G24: =F24+F24*$D$3 | H24: =G24+G24*$D$3 | I24: =H24+H24*$E$3 | J24: =I24+I24*$E$3 | K24: =J24+J24*$E$3 | L24: =K24+K24*$F$3 | M24: =L24+L24*$F$3 | N24: =M24+M24*$F$3 | O24: =SUM(C24:N24) | Q24: =IF($O$52=0,0,O24/$O$52)
B25: Total Sales | C25: =$D$10*C24 | D25: =$D$10*D24 | E25: =$D$10*E24 | F25: =$D$10*F24 | G25: =$D$10*G24 | H25: =$D$10*H24 | I25: =$D$10*I24 | J25: =$D$10*J24 | ... N25: =$D$10*N24 | O25: =SUM(C25:N25) | P25: =(P26+P27) | Q25: =IF($O$53=0,0,O25/$O$53)
B26: Total COGS | C26: =$E$10*C24 | D26: =$E$10*D24 | E26: =$E$10*E24 | F26: =$E$10*F24 | G26: =$E$10*G24 | H26: =$E$10*H24 | I26: =$E$10*I24 | J26: =$E$10*J24 | ... N26: =$E$10*N24 | O26: =SUM(C26:N26) | P26: =IF(O25=0,0,O26/O25) | Q26: =IF($O$54=0,0,O26/$O$54)
B27: Margin | C27: =C25-C26 | D27: =D25-D26 | E27: =E25-E26 | F27: =F25-F26 | G27: =G25-G26 | H27: =H25-H26 | I27: =I25-I26 | J27: =J25-J26 | ... N27: =N25-N26 | O27: =SUM(C27:N27) | P27: =IF(O25=0,0,O27/O25) | Q27: =IF($O$55=0,0,O27/$O$55)
B29: =IF(ISBLANK(B11), "Product 3", B11)
B30: =IF(ISBLANK(C11), "Units Sold", Unit3& " Sold") | D30: =C30+C30*$C$3 | E30: =D30+D30*$C$3 | F30: =E30+E30*$D$3 | G30: =F30+F30*$D$3 | H30: =G30+G30*$D$3 | I30: =H30+H30*$E$3 | J30: =I30+I30*$E$3 | K30: =J30+J30*$E$3 | L30: =K30+K30*$F$3 | M30: =L30+L30*$F$3 | N30: =M30+M30*$F$3 | O30: =SUM(C30:N30) | Q30: =IF($O$52=0,0,O30/$O$52)
B31: Total Sales | C31: =$D$11*C30 | D31: =$D$11*D30 | E31: =$D$11*E30 | F31: =$D$11*F30 | G31: =$D$11*G30 | H31: =$D$11*H30 | I31: =$D$11*I30 | J31: =$D$11*J30 | ... N31: =$D$11*N30 | O31: =SUM(C31:N31) | P31: =(P32+P33) | Q31: =IF($O$53=0,0,O31/$O$53)
B32: Total COGS | C32: =$E$11*C30 | D32: =$E$11*D30 | E32: =$E$11*E30 | F32: =$E$11*F30 | G32: =$E$11*G30 | H32: =$E$11*H30 | I32: =$E$11*I30 | J32: =$E$11*J30 | ... N32: =$E$11*N30 | O32: =SUM(C32:N32) | P32: =IF(O31=0,0,O32/O31) | Q32: =IF($O$54=0,0,O32/$O$54)
B33: Margin | C33: =C31-C32 | D33: =D31-D32 | E33: =E31-E32 | F33: =F31-F32 | G33: =G31-G32 | H33: =H31-H32 | I33: =I31-I32 | J33: =J31-J32 | ... N33: =N31-N32 | O33: =SUM(C33:N33) | P33: =IF(O31=0,0,O33/O31) | Q33: =IF($O$55=0,0,O33/$O$55)
B35: =IF(ISBLANK(B12), "Product 4", B12)
B36: =IF(ISBLANK(C12), "Units Sold", Unit4& " Sold") | D36: =C36+C36*$C$3 | E36: =D36+D36*$C$3 | F36: =E36+E36*$D$3 | G36: =F36+F36*$D$3 | H36: =G36+G36*$D$3 | I36: =H36+H36*$E$3 | J36: =I36+I36*$E$3 | K36: =J36+J36*$E$3 | L36: =K36+K36*$F$3 | M36: =L36+L36*$F$3 | N36: =M36+M36*$F$3 | O36: =SUM(C36:N36) | Q36: =IF($O$52=0,0,O36/$O$52)
B37: Total Sales | C37: =$D$12*C36 | D37: =$D$12*D36 | E37: =$D$12*E36 | F37: =$D$12*F36 | G37: =$D$12*G36 | H37: =$D$12*H36 | I37: =$D$12*I36 | J37: =$D$12*J36 | ... N37: =$D$12*N36 | O37: =SUM(C37:N37) | P37: =(P38+P39) | Q37: =IF($O$53=0,0,O37/$O$53)
B38: Total COGS | C38: =$E$12*C36 | D38: =$E$12*D36 | E38: =$E$12*E36 | F38: =$E$12*F36 | G38: =$E$12*G36 | H38: =$E$12*H36 | I38: =$E$12*I36 | J38: =$E$12*J36 | ... N38: =$E$12*N36 | O38: =SUM(C38:N38) | P38: =IF(O37=0,0,O38/O37) | Q38: =IF($O$54=0,0,O38/$O$54)
B39: Margin | C39: =C37-C38 | D39: =D37-D38 | E39: =E37-E38 | F39: =F37-F38 | G39: =G37-G38 | H39: =H37-H38 | I39: =I37-I38 | J39: =J37-J38 | ... N39: =N37-N38 | O39: =SUM(C39:N39) | P39: =IF(O37=0,0,O39/O37) | Q39: =IF($O$55=0,0,O39/$O$55)
B41: =IF(ISBLANK(B13), "Product 5", B13)
B42: =IF(ISBLANK(C13), "Units Sold", Unit5& " Sold") | D42: =C42+C42*$C$3 | E42: =D42+D42*$C$3 | F42: =E42+E42*$D$3 | G42: =F42+F42*$D$3 | H42: =G42+G42*$D$3 | I42: =H42+H42*$E$3 | J42: =I42+I42*$E$3 | K42: =J42+J42*$E$3 | L42: =K42+K42*$F$3 | M42: =L42+L42*$F$3 | N42: =M42+M42*$F$3 | O42: =SUM(C42:N42) | Q42: =IF($O$52=0,0,O42/$O$52)
B43: Total Sales | C43: =$D$13*C42 | D43: =$D$13*D42 | E43: =$D$13*E42 | F43: =$D$13*F42 | G43: =$D$13*G42 | H43: =$D$13*H42 | I43: =$D$13*I42 | J43: =$D$13*J42 | ... N43: =$D$13*N42 | O43: =SUM(C43:N43) | P43: =(P44+P45) | Q43: =IF($O$53=0,0,O43/$O$53)
B44: Total COGS | C44: =$E$13*C42 | D44: =$E$13*D42 | E44: =$E$13*E42 | F44: =$E$13*F42 | G44: =$E$13*G42 | H44: =$E$13*H42 | I44: =$E$13*I42 | J44: =$E$13*J42 | ... N44: =$E$13*N42 | O44: =SUM(C44:N44) | P44: =IF(O43=0,0,O44/O43) | Q44: =IF($O$54=0,0,O44/$O$54)
B45: Margin | C45: =C43-C44 | D45: =D43-D44 | E45: =E43-E44 | F45: =F43-F44 | G45: =G43-G44 | H45: =H43-H44 | I45: =I43-I44 | J45: =J43-J44 | ... N45: =N43-N44 | O45: =SUM(C45:N45) | P45: =IF(O43=0,0,O45/O43) | Q45: =IF($O$55=0,0,O45/$O$55)
B47: =IF(ISBLANK(B14), "Product 6", B14)
B48: =IF(ISBLANK(C14), "Units Sold", Unit6& " Sold") | D48: =C48+C48*$C$3 | E48: =D48+D48*$C$3 | F48: =E48+E48*$D$3 | G48: =F48+F48*$D$3 | H48: =G48+G48*$D$3 | I48: =H48+H48*$E$3 | J48: =I48+I48*$E$3 | K48: =J48+J48*$E$3 | L48: =K48+K48*$F$3 | M48: =L48+L48*$F$3 | N48: =M48+M48*$F$3 | O48: =SUM(C48:N48) | Q48: =IF($O$52=0,0,O48/$O$52)
...

Sheet 3b-SalesForecastYrs1-3
B2: Sales Forecast Year 1-3
B4: Prepared by: | C4: Company Name:
B5: =IF(ISBLANK(Directions!C10), "Owner", Directions!C10) | C5: =IF(ISBLANK(Directions!D10), "Company 1", Directions!D10)
B7: Monthly Growth Rate Year 2 | C7: 0.03
B8: Monthly Growth Rate Year 3 | C8: 0.02
A10: Product Lines | B10: Year 1 Totals | C10: ='2a-PayrollYear1'!F7 | D10: ='2a-PayrollYear1'!G7 | E10: ='2a-PayrollYear1'!H7 | F10: ='2a-PayrollYear1'!I7 | G10: ='2a-PayrollYear1'!J7 | H10: ='2a-PayrollYear1'!K7 | I10: ='2a-PayrollYear1'!L7 | J10: ='2a-PayrollYear1'!M7 | ... N10: ='2a-PayrollYear1'!Q7 | O10: Year 2 Totals | P10: Category Breakdown | Q10: Category / Total | R10: ='2a-PayrollYear1'!F7 | S10: ='2a-PayrollYear1'!G7 | T10: ='2a-PayrollYear1'!H7 | U10: ='2a-PayrollYear1'!I7 | V10: ='2a-PayrollYear1'!J7 | W10: ='2a-PayrollYear1'!K7 | X10: ='2a-PayrollYear1'!L7 | Y10: ='2a-PayrollYear1'!M7 | ... AC10: ='2a-PayrollYear1'!Q7 | AD10: Year 3 Totals | AE10: Category Breakdown | AF10: Category / Total
A11: ='3a-SalesForecastYear1'!B17
A12: =Unit1& " Sold" | B12: =Unit1_Annual | C12: ='3a-SalesForecastYear1'!N18 | D12: =C12+C12*$C$7 | E12: =D12+D12*$C$7 | F12: =E12+E12*$C$7 | G12: =F12+F12*$C$7 | H12: =G12+G12*$C$7 | I12: =H12+H12*$C$7 | J12: =I12+I12*$C$7 | K12: =J12+J12*$C$7 | ... N12: =M12+M12*$C$7 | O12: =SUM(C12:N12) | Q12: =IF($O$46=0,0,O12/$O$46) | R12: =N12 | S12: =R12+R12*$C$8 | T12: =S12+S12*$C$8 | U12: =T12+T12*$C$8 | V12: =U12+U12*$C$8 | W12: =V12+V12*$C$8 | X12: =W12+W12*$C$8 | Y12: =X12+X12*$C$8 | Z12: =Y12+Y12*$C$8 | ... AC12: =AB12+AB12*$C$8 | AD12: =SUM(R12:AC12) | AF12: =IF($AD$46=0,0,AD12/$AD$46)
A13: Total Sales | B13: =Category1_Annual_Sales | C13: =+C12*'3a-SalesForecastYear1'!$D$9 | D13: =+D12*'3a-SalesForecastYear1'!$D$9 | E13: =+E12*'3a-SalesForecastYear1'!$D$9 | F13: =+F12*'3a-SalesForecastYear1'!$D$9 | G13: =+G12*'3a-SalesForecastYear1'!$D$9 | H13: =+H12*'3a-SalesForecastYear1'!$D$9 | I13: =+I12*'3a-SalesForecastYear1'!$D$9 | J13: =+J12*'3a-SalesForecastYear1'!$D$9 | ... N13: =+N12*'3a-SalesForecastYear1'!$D$9 | O13: =SUM(C13:N13) | P13: =(P14+P15) | Q13: =IF($O$47=0,0,O13/$O$47) | R13: =+R12*'3a-SalesForecastYear1'!$D$9 | S13: =+S12*'3a-SalesForecastYear1'!$D$9 | T13: =+T12*'3a-SalesForecastYear1'!$D$9 | U13: =+U12*'3a-SalesForecastYear1'!$D$9 | V13: =+V12*'3a-SalesForecastYear1'!$D$9 | W13: =+W12*'3a-SalesForecastYear1'!$D$9 | X13: =+X12*'3a-SalesForecastYear1'!$D$9 | Y13: =+Y12*'3a-SalesForecastYear1'!$D$9 | ... AC13: =+AC12*'3a-SalesForecastYear1'!$D$9 | AD13: =SUM(R13:AC13) | AE13: =(AE14+AE15) | AF13: =IF($AD$47=0,0,AD13/$AD$47)
A14: Total COGS | B14: ='3a-SalesForecastYear1'!O20 | C14: =+C12*'3a-SalesForecastYear1'!$E$9 | D14: =+D12*'3a-SalesForecastYear1'!$E$9 | E14: =+E12*'3a-SalesForecastYear1'!$E$9 | F14: =+F12*'3a-SalesForecastYear1'!$E$9 | G14: =+G12*'3a-SalesForecastYear1'!$E$9 | H14: =+H12*'3a-SalesForecastYear1'!$E$9 | I14: =+I12*'3a-SalesForecastYear1'!$E$9 | J14: =+J12*'3a-SalesForecastYear1'!$E$9 | ... N14: =+N12*'3a-SalesForecastYear1'!$E$9 | O14: =SUM(C14:N14) | P14: =IF(O13=0,0,O14/O13) | Q14: =IF($O$48=0,0,O14/$O$48) | R14: =+R12*'3a-SalesForecastYear1'!$E$9 | S14: =+S12*'3a-SalesForecastYear1'!$E$9 | T14: =+T12*'3a-SalesForecastYear1'!$E$9 | U14: =+U12*'3a-SalesForecastYear1'!$E$9 | V14: =+V12*'3a-SalesForecastYear1'!$E$9 | W14: =+W12*'3a-SalesForecastYear1'!$E$9 | X14: =+X12*'3a-SalesForecastYear1'!$E$9 | Y14: =+Y12*'3a-SalesForecastYear1'!$E$9 | ... AC14: =+AC12*'3a-SalesForecastYear1'!$E$9 | AD14: =SUM(R14:AC14) | AE14: =IF(AD13=0,0,AD14/AD13) | AF14: =IF($AD$48=0,0,AD14/$AD$48)
A15: Total Margin | B15: ='3a-SalesForecastYear1'!O21 | C15: =C13-C14 | D15: =D13-D14 | E15: =E13-E14 | F15: =F13-F14 | G15: =G13-G14 | H15: =H13-H14 | I15: =I13-I14 | J15: =J13-J14 | ... N15: =N13-N14 | O15: =SUM(C15:N15) | P15: =IF(O13=0,0,O15/O13) | Q15: =IF($O$49=0,0,O15/$O$49) | R15: =R13-R14 | S15: =S13-S14 | T15: =T13-T14 | U15: =U13-U14 | V15: =V13-V14 | W15: =W13-W14 | X15: =X13-X14 | Y15: =Y13-Y14 | ... AC15: =AC13-AC14 | AD15: =SUM(R15:AC15) | AE15: =IF(AD13=0,0,AD15/AD13) | AF15: =IF($AD$49=0,0,AD15/$AD$49)
A17: ='3a-SalesForecastYear1'!B23
A18: =Unit2& " Sold" | B18: =Unit2_Annual | C18: ='3a-SalesForecastYear1'!N24 | D18: =C18+C18*$C$7 | E18: =D18+D18*$C$7 | F18: =E18+E18*$C$7 | G18: =F18+F18*$C$7 | H18: =G18+G18*$C$7 | I18: =H18+H18*$C$7 | J18: =I18+I18*$C$7 | K18: =J18+J18*$C$7 | ... N18: =M18+M18*$C$7 | O18: =SUM(C18:N18) | Q18: =IF($O$46=0,0,O18/$O$46) | R18: =N18 | S18: =R18+R18*$C$8 | T18: =S18+S18*$C$8 | U18: =T18+T18*$C$8 | V18: =U18+U18*$C$8 | W18: =V18+V18*$C$8 | X18: =W18+W18*$C$8 | Y18: =X18+X18*$C$8 | Z18: =Y18+Y18*$C$8 | ... AC18: =AB18+AB18*$C$8 | AD18: =SUM(R18:AC18) | AF18: =IF($AD$46=0,0,AD18/$AD$46)
A19: Total Sales | B19: =Category2_Annual_Sales | C19: =+C18*'3a-SalesForecastYear1'!$D$10 | D19: =+D18*'3a-SalesForecastYear1'!$D$10 | E19: =+E18*'3a-SalesForecastYear1'!$D$10 | F19: =+F18*'3a-SalesForecastYear1'!$D$10 | G19: =+G18*'3a-SalesForecastYear1'!$D$10 | H19: =+H18*'3a-SalesForecastYear1'!$D$10 | I19: =+I18*'3a-SalesForecastYear1'!$D$10 | J19: =+J18*'3a-SalesForecastYear1'!$D$10 | ... N19: =+N18*'3a-SalesForecastYear1'!$D$10 | O19: =SUM(C19:N19) | P19: =(P20+P21) | Q19: =IF($O$47=0,0,O19/$O$47) | R19: =+R18*'3a-SalesForecastYear1'!$D$10 | S19: =+S18*'3a-SalesForecastYear1'!$D$10 | T19: =+T18*'3a-SalesForecastYear1'!$D$10 | U19: =+U18*'3a-SalesForecastYear1'!$D$10 | V19: =+V18*'3a-SalesForecastYear1'!$D$10 | W19: =+W18*'3a-SalesForecastYear1'!$D$10 | X19: =+X18*'3a-SalesForecastYear1'!$D$10 | Y19: =+Y18*'3a-SalesForecastYear1'!$D$10 | ... AC19: =+AC18*'3a-SalesForecastYear1'!$D$10 | AD19: =SUM(R19:AC19) | AE19: =(AE20+AE21) | AF19: =IF($AD$47=0,0,AD19/$AD$47)
A20: Total COGS | B20: ='3a-SalesForecastYear1'!O26 | C20: =+C18*'3a-SalesForecastYear1'!$E$10 | D20: =+D18*'3a-SalesForecastYear1'!$E$10 | E20: =+E18*'3a-SalesForecastYear1'!$E$10 | F20: =+F18*'3a-SalesForecastYear1'!$E$10 | G20: =+G18*'3a-SalesForecastYear1'!$E$10 | H20: =+H18*'3a-SalesForecastYear1'!$E$10 | I20: =+I18*'3a-SalesForecastYear1'!$E$10 | J20: =+J18*'3a-SalesForecastYear1'!$E$10 | ... N20: =+N18*'3a-SalesForecastYear1'!$E$10 | O20: =SUM(C20:N20) | P20: =IF(O19=0,0,O20/O19) | Q20: =IF($O$48=0,0,O20/$O$48) | R20: =+R18*'3a-SalesForecastYear1'!$E$10 | S20: =+S18*'3a-SalesForecastYear1'!$E$10 | T20: =+T18*'3a-SalesForecastYear1'!$E$10 | U20: =+U18*'3a-SalesForecastYear1'!$E$10 | V20: =+V18*'3a-SalesForecastYear1'!$E$10 | W20: =+W18*'3a-SalesForecastYear1'!$E$10 | X20: =+X18*'3a-SalesForecastYear1'!$E$10 | Y20: =+Y18*'3a-SalesForecastYear1'!$E$10 | ... AC20: =+AC18*'3a-SalesForecastYear1'!$E$10 | AD20: =SUM(R20:AC20) | AE20: =IF(AD19=0,0,AD20/AD19) | AF20: =IF($AD$48=0,0,AD20/$AD$48)
A21: Margin | B21: ='3a-SalesForecastYear1'!O27 | C21: =C19-C20 | D21: =D19-D20 | E21: =E19-E20 | F21: =F19-F20 | G21: =G19-G20 | H21: =H19-H20 | I21: =I19-I20 | J21: =J19-J20 | ... N21: =N19-N20 | O21: =SUM(C21:N21) | P21: =IF(O19=0,0,O21/O19) | Q21: =IF($O$49=0,0,O21/$O$49) | R21: =R19-R20 | S21: =S19-S20 | T21: =T19-T20 | U21: =U19-U20 | V21: =V19-V20 | W21: =W19-W20 | X21: =X19-X20 | Y21: =Y19-Y20 | ... AC21: =AC19-AC20 | AD21: =SUM(R21:AC21) | AE21: =IF(AD19=0,0,AD21/AD19) | AF21: =IF($AD$49=0,0,AD21/$AD$49)
A23: ='3a-SalesForecastYear1'!B29
A24: =Unit3& " Sold" | B24: =Unit3_Annual | C24: ='3a-SalesForecastYear1'!N30 | D24: =C24+C24*$C$7 | E24: =D24+D24*$C$7 | F24: =E24+E24*$C$7 | G24: =F24+F24*$C$7 | H24: =G24+G24*$C$7 | I24: =H24+H24*$C$7 | J24: =I24+I24*$C$7 | K24: =J24+J24*$C$7 | ... N24: =M24+M24*$C$7 | O24: =SUM(C24:N24) | Q24: =IF($O$46=0,0,O24/$O$46) | R24: =N24 | S24: =R24+R24*$C$8 | T24: =S24+S24*$C$8 | U24: =T24+T24*$C$8 | V24: =U24+U24*$C$8 | W24: =V24+V24*$C$8 | X24: =W24+W24*$C$8 | Y24: =X24+X24*$C$8 | Z24: =Y24+Y24*$C$8 | ... AC24: =AB24+AB24*$C$8 | AD24: =SUM(R24:AC24) | AF24: =IF($AD$46=0,0,AD24/$AD$46)
A25: Total Sales | B25: =Category3_Annual_Sales | C25: =+C24*'3a-SalesForecastYear1'!$D$11 | D25: =+D24*'3a-SalesForecastYear1'!$D$11 | E25: =+E24*'3a-SalesForecastYear1'!$D$11 | F25: =+F24*'3a-SalesForecastYear1'!$D$11 | G25: =+G24*'3a-SalesForecastYear1'!$D$11 | H25: =+H24*'3a-SalesForecastYear1'!$D$11 | I25: =+I24*'3a-SalesForecastYear1'!$D$11 | J25: =+J24*'3a-SalesForecastYear1'!$D$11 | ... N25: =+N24*'3a-SalesForecastYear1'!$D$11 | O25: =SUM(C25:N25) | P25: =(P26+P27) | Q25: =IF($O$47=0,0,O25/$O$47) | R25: =+R24*'3a-SalesForecastYear1'!$D$11 | S25: =+S24*'3a-SalesForecastYear1'!$D$11 | T25: =+T24*'3a-SalesForecastYear1'!$D$11 | U25: =+U24*'3a-SalesForecastYear1'!$D$11 | V25: =+V24*'3a-SalesForecastYear1'!$D$11 | W25: =+W24*'3a-SalesForecastYear1'!$D$11 | X25: =+X24*'3a-SalesForecastYear1'!$D$11 | Y25: =+Y24*'3a-SalesForecastYear1'!$D$11 | ... AC25: =+AC24*'3a-SalesForecastYear1'!$D$11 | AD25: =SUM(R25:AC25) | AE25: =(AE26+AE27) | AF25: =IF($AD$47=0,0,AD25/$AD$47)
A26: Total COGS | B26: ='3a-SalesForecastYear1'!O32 | C26: =+C24*'3a-SalesForecastYear1'!$E$11 | D26: =+D24*'3a-SalesForecastYear1'!$E$11 | E26: =+E24*'3a-SalesForecastYear1'!$E$11 | F26: =+F24*'3a-SalesForecastYear1'!$E$11 | G26: =+G24*'3a-SalesForecastYear1'!$E$11 | H26: =+H24*'3a-SalesForecastYear1'!$E$11 | I26: =+I24*'3a-SalesForecastYear1'!$E$11 | J26: =+J24*'3a-SalesForecastYear1'!$E$11 | ... N26: =+N24*'3a-SalesForecastYear1'!$E$11 | O26: =SUM(C26:N26) | P26: =IF(O25=0,0,O26/O25) | Q26: =IF($O$48=0,0,O26/$O$48) | R26: =+R24*'3a-SalesForecastYear1'!$E$11 | S26: =+S24*'3a-SalesForecastYear1'!$E$11 | T26: =+T24*'3a-SalesForecastYear1'!$E$11 | U26: =+U24*'3a-SalesForecastYear1'!$E$11 | V26: =+V24*'3a-SalesForecastYear1'!$E$11 | W26: =+W24*'3a-SalesForecastYear1'!$E$11 | X26: =+X24*'3a-SalesForecastYear1'!$E$11 | Y26: =+Y24*'3a-SalesForecastYear1'!$E$11 | ... AC26: =+AC24*'3a-SalesForecastYear1'!$E$11 | AD26: =SUM(R26:AC26) | AE26: =IF(AD25=0,0,AD26/AD25) | AF26: =IF($AD$48=0,0,AD26/$AD$48)
A27: Margin | B27: ='3a-SalesForecastYear1'!O33 | C27: =C25-C26 | D27: =D25-D26 | E27: =E25-E26 | F27: =F25-F26 | G27: =G25-G26 | H27: =H25-H26 | I27: =I25-I26 | J27: =J25-J26 | ... N27: =N25-N26 | O27: =SUM(C27:N27) | P27: =IF(O25=0,0,O27/O25) | Q27: =IF($O$49=0,0,O27/$O$49) | R27: =R25-R26 | S27: =S25-S26 | T27: =T25-T26 | U27: =U25-U26 | V27: =V25-V26 | W27: =W25-W26 | X27: =X25-X26 | Y27: =Y25-Y26 | ... AC27: =AC25-AC26 | AD27: =SUM(R27:AC27) | AE27: =IF(AD25=0,0,AD27/AD25) | AF27: =IF($AD$49=0,0,AD27/$AD$49)
A29: ='3a-SalesForecastYear1'!B35
A30: =Unit4& " Sold" | B30: =Unit4_Annual | C30: ='3a-SalesForecastYear1'!N36 | D30: =C30+C30*$C$7 | E30: =D30+D30*$C$7 | F30: =E30+E30*$C$7 | G30: =F30+F30*$C$7 | H30: =G30+G30*$C$7 | I30: =H30+H30*$C$7 | J30: =I30+I30*$C$7 | K30: =J30+J30*$C$7 | ... N30: =M30+M30*$C$7 | O30: =SUM(C30:N30) | Q30: =IF($O$46=0,0,O30/$O$46) | R30: =N30 | S30: =R30+R30*$C$8 | T30: =S30+S30*$C$8 | U30: =T30+T30*$C$8 | V30: =U30+U30*$C$8 | W30: =V30+V30*$C$8 | X30: =W30+W30*$C$8 | Y30: =X30+X30*$C$8 | Z30: =Y30+Y30*$C$8 | ... AC30: =AB30+AB30*$C$8 | AD30: =SUM(R30:AC30) | AF30: =IF($AD$46=0,0,AD30/$AD$46)
A31: Total Sales | B31: =Category4_Annual_Sales | C31: =+C30*'3a-SalesForecastYear1'!$D$12 | D31: =+D30*'3a-SalesForecastYear1'!$D$12 | E31: =+E30*'3a-SalesForecastYear1'!$D$12 | F31: =+F30*'3a-SalesForecastYear1'!$D$12 | G31: =+G30*'3a-SalesForecastYear1'!$D$12 | H31: =+H30*'3a-SalesForecastYear1'!$D$12 | I31: =+I30*'3a-SalesForecastYear1'!$D$12 | J31: =+J30*'3a-SalesForecastYear1'!$D$12 | ... N31: =+N30*'3a-SalesForecastYear1'!$D$12 | O31: =SUM(C31:N31) | P31: =(P32+P33) | Q31: =IF($O$47=0,0,O31/$O$47) | R31: =+R30*'3a-SalesForecastYear1'!$D$12 | S31: =+S30*'3a-SalesForecastYear1'!$D$12 | T31: =+T30*'3a-SalesForecastYear1'!$D$12 | U31: =+U30*'3a-SalesForecastYear1'!$D$12 | V31: =+V30*'3a-SalesForecastYear1'!$D$12 | W31: =+W30*'3a-SalesForecastYear1'!$D$12 | X31: =+X30*'3a-SalesForecastYear1'!$D$12 | Y31: =+Y30*'3a-SalesForecastYear1'!$D$12 | ... AC31: =+AC30*'3a-SalesForecastYear1'!$D$12 | AD31: =SUM(R31:AC31) | AE31: =(AE32+AE33) | AF31: =IF($AD$47=0,0,AD31/$AD$47)
A32: Total COGS | B32: ='3a-SalesForecastYear1'!O38 | C32: =+C30*'3a-SalesForecastYear1'!$E$12 | D32: =+D30*'3a-SalesForecastYear1'!$E$12 | E32: =+E30*'3a-SalesForecastYear1'!$E$12 | F32: =+F30*'3a-SalesForecastYear1'!$E$12 | G32: =+G30*'3a-SalesForecastYear1'!$E$12 | H32: =+H30*'3a-SalesForecastYear1'!$E$12 | I32: =+I30*'3a-SalesForecastYear1'!$E$12 | J32: =+J30*'3a-SalesForecastYear1'!$E$12 | ... N32: =+N30*'3a-SalesForecastYear1'!$E$12 | O32: =SUM(C32:N32) | P32: =IF(O31=0,0,O32/O31) | Q32: =IF($O$48=0,0,O32/$O$48) | R32: =+R30*'3a-SalesForecastYear1'!$E$12 | S32: =+S30*'3a-SalesForecastYear1'!$E$12 | T32: =+T30*'3a-SalesForecastYear1'!$E$12 | U32: =+U30*'3a-SalesForecastYear1'!$E$12 | V32: =+V30*'3a-SalesForecastYear1'!$E$12 | W32: =+W30*'3a-SalesForecastYear1'!$E$12 | X32: =+X30*'3a-SalesForecastYear1'!$E$12 | Y32: =+Y30*'3a-SalesForecastYear1'!$E$12 | ... AC32: =+AC30*'3a-SalesForecastYear1'!$E$12 | AD32: =SUM(R32:AC32) | AE32: =IF(AD31=0,0,AD32/AD31) | AF32: =IF($AD$48=0,0,AD32/$AD$48)
A33: Margin | B33: ='3a-SalesForecastYear1'!O39 | C33: =C31-C32 | D33: =D31-D32 | E33: =E31-E32 | F33: =F31-F32 | G33: =G31-G32 | H33: =H31-H32 | I33: =I31-I32 | J33: =J31-J32 | ... N33: =N31-N32 | O33: =SUM(C33:N33) | P33: =IF(O31=0,0,O33/O31) | Q33: =IF($O$49=0,0,O33/$O$49) | R33: =R31-R32 | S33: =S31-S32 | T33: =T31-T32 | U33: =U31-U32 | V33: =V31-V32 | W33: =W31-W32 | X33: =X31-X32 | Y33: =Y31-Y32 | ... AC33: =AC31-AC32 | AD33: =SUM(R33:AC33) | AE33: =IF(AD31=0,0,AD33/AD31) | AF33: =IF($AD$49=0,0,AD33/$AD$49)
A35: ='3a-SalesForecastYear1'!B41
A36: =Unit5& " Sold" | B36: =Unit5_Annual | C36: ='3a-SalesForecastYear1'!N42 | D36: =C36+C36*$C$7 | E36: =D36+D36*$C$7 | F36: =E36+E36*$C$7 | G36: =F36+F36*$C$7 | H36: =G36+G36*$C$7 | I36: =H36+H36*$C$7 | J36: =I36+I36*$C$7 | K36: =J36+J36*$C$7 | ... N36: =M36+M36*$C$7 | O36: =SUM(C36:N36) | Q36: =IF($O$46=0,0,O36/$O$46) | R36: =N36 | S36: =R36+R36*$C$8 | T36: =S36+S36*$C$8 | U36: =T36+T36*$C$8 | V36: =U36+U36*$C$8 | W36: =V36+V36*$C$8 | X36: =W36+W36*$C$8 | Y36: =X36+X36*$C$8 | Z36: =Y36+Y36*$C$8 | ... AC36: =AB36+AB36*$C$8 | AD36: =SUM(R36:AC36) | AF36: =IF($AD$46=0,0,AD36/$AD$46)
A37: Total Sales | B37: =Category5_Annual_Sales | C37: =+C36*'3a-SalesForecastYear1'!$D$13 | D37: =+D36*'3a-SalesForecastYear1'!$D$13 | E37: =+E36*'3a-SalesForecastYear1'!$D$13 | F37: =+F36*'3a-SalesForecastYear1'!$D$13 | G37: =+G36*'3a-SalesForecastYear1'!$D$13 | H37: =+H36*'3a-SalesForecastYear1'!$D$13 | I37: =+I36*'3a-SalesForecastYear1'!$D$13 | J37: =+J36*'3a-SalesForecastYear1'!$D$13 | ... N37: =+N36*'3a-SalesForecastYear1'!$D$13 | O37: =SUM(C37:N37) | P37: =(P38+P39) | Q37: =IF($O$47=0,0,O37/$O$47) | R37: =+R36*'3a-SalesForecastYear1'!$D$13 | S37: =+S36*'3a-SalesForecastYear1'!$D$13 | T37: =+T36*'3a-SalesForecastYear1'!$D$13 | U37: =+U36*'3a-SalesForecastYear1'!$D$13 | V37: =+V36*'3a-SalesForecastYear1'!$D$13 | W37: =+W36*'3a-SalesForecastYear1'!$D$13 | X37: =+X36*'3a-SalesForecastYear1'!$D$13 | Y37: =+Y36*'3a-SalesForecastYear1'!$D$13 | ... AC37: =+AC36*'3a-SalesForecastYear1'!$D$13 | AD37: =SUM(R37:AC37) | AE37: =(AE38+AE39) | AF37: =IF($AD$47=0,0,AD37/$AD$47)
A38: Total COGS | B38: ='3a-SalesForecastYear1'!O44 | C38: =+C36*'3a-SalesForecastYear1'!$E$13 | D38: =+D36*'3a-SalesForecastYear1'!$E$13 | E38: =+E36*'3a-SalesForecastYear1'!$E$13 | F38: =+F36*'3a-SalesForecastYear1'!$E$13 | G38: =+G36*'3a-SalesForecastYear1'!$E$13 | H38: =+H36*'3a-SalesForecastYear1'!$E$13 | I38: =+I36*'3a-SalesForecastYear1'!$E$13 | J38: =+J36*'3a-SalesForecastYear1'!$E$13 | ... N38: =+N36*'3a-SalesForecastYear1'!$E$13 | O38: =SUM(C38:N38) | P38: =IF(O37=0,0,O38/O37) | Q38: =IF($O$48=0,0,O38/$O$48) | R38: =+R36*'3a-SalesForecastYear1'!$E$13 | S38: =+S36*'3a-SalesForecastYear1'!$E$13 | T38: =+T36*'3a-SalesForecastYear1'!$E$13 | U38: =+U36*'3a-SalesForecastYear1'!$E$13 | V38: =+V36*'3a-SalesForecastYear1'!$E$13 | W38: =+W36*'3a-SalesForecastYear1'!$E$13 | X38: =+X36*'3a-SalesForecastYear1'!$E$13 | Y38: =+Y36*'3a-SalesForecastYear1'!$E$13 | ... AC38: =+AC36*'3a-SalesForecastYear1'!$E$13 | AD38: =SUM(R38:AC38) | AE38: =IF(AD37=0,0,AD38/AD37) | AF38: =IF($AD$48=0,0,AD38/$AD$48)
A39: Margin | B39: ='3a-SalesForecastYear1'!O45 | C39: =C37-C38 | D39: =D37-D38 | E39: =E37-E38 | F39: =F37-F38 | G39: =G37-G38 | H39: =H37-H38 | I39: =I37-I38 | J39: =J37-J38 | ... N39: =N37-N38 | O39: =SUM(C39:N39) | P39: =IF(O37=0,0,O39/O37) | Q39: =IF($O$49=0,0,O39/$O$49) | R39: =R37-R38 | S39: =S37-S38 | T39: =T37-T38 | U39: =U37-U38 | V39: =V37-V38 | W39: =W37-W38 | X39: =X37-X38 | Y39: =Y37-Y38 | ... AC39: =AC37-AC38 | AD39: =SUM(R39:AC39) | AE39: =IF(AD37=0,0,AD39/AD37) | AF39: =IF($AD$49=0,0,AD39/$AD$49)
A41: ='3a-SalesForecastYear1'!B47
A42: =Unit6& " Sold" | B42: =Unit6_Annual | C42: ='3a-SalesForecastYear1'!N48 | D42: =C42+C42*$C$7 | E42: =D42+D42*$C$7 | F42: =E42+E42*$C$7 | G42: =F42+F42*$C$7 | H42: =G42+G42*$C$7 | I42: =H42+H42*$C$7 | J42: =I42+I42*$C$7 | K42: =J42+J42*$C$7 | ... N42: =M42+M42*$C$7 | O42: =SUM(C42:N42) | Q42: =IF($O$46=0,0,O42/$O$46) | R42: =N42 | S42: =R42+R42*$C$8 | T42: =S42+S42*$C$8 | U42: =T42+T42*$C$8 | V42: =U42+U42*$C$8 | W42: =V42+V42*$C$8 | X42: =W42+W42*$C$8 | Y42: =X42+X42*$C$8 | Z42: =Y42+Y42*$C$8 | ... AC42: =AB42+AB42*$C$8 | AD42: =SUM(R42:AC42) | AF42: =IF($AD$46=0,0,AD42/$AD$46)
A43: Total Sales | B43: =Category6_Annual_Sales | C43: =+C42*'3a-SalesForecastYear1'!$D$14 | D43: =+D42*'3a-SalesForecastYear1'!$D$14 | E43: =+E42*'3a-SalesForecastYear1'!$D$14 | F43: =+F42*'3a-SalesForecastYear1'!$D$14 | G43: =+G42*'3a-SalesForecastYear1'!$D$14 | H43: =+H42*'3a-SalesForecastYear1'!$D$14 | I43: =+I42*'3a-SalesForecastYear1'!$D$14 | J43: =+J42*'3a-SalesForecastYear1'!$D$14 | ... N43: =+N42*'3a-SalesForecastYear1'!$D$14 | O43: =SUM(C43:N43) | P43: =(P44+P45) | Q43: =IF($O$47=0,0,O43/$O$47) | R43: =+R42*'3a-SalesForecastYear1'!$D$14 | S43: =+S42*'3a-SalesForecastYear1'!$D$14 | T43: =+T42*'3a-SalesForecastYear1'!$D$14 | U43: =+U42*'3a-SalesForecastYear1'!$D$14 | V43: =+V42*'3a-SalesForecastYear1'!$D$14 | W43: =+W42*'3a-SalesForecastYear1'!$D$14 | X43: =+X42*'3a-SalesForecastYear1'!$D$14 | Y43: =+Y42*'3a-SalesForecastYear1'!$D$14 | ... AC43: =+AC42*'3a-SalesForecastYear1'!$D$14 | AD43: =SUM(R43:AC43) | AE43: =(AE44+AE45) | AF43: =IF($AD$47=0,0,AD43/$AD$47)
A44: Total COGS | B44: ='3a-SalesForecastYear1'!O50 | C44: =+C42*'3a-SalesForecastYear1'!$E$14 | D44: =+D42*'3a-SalesForecastYear1'!$E$14 | E44: =+E42*'3a-SalesForecastYear1'!$E$14 | F44: =+F42*'3a-SalesForecastYear1'!$E$14 | G44: =+G42*'3a-SalesForecastYear1'!$E$14 | H44: =+H42*'3a-SalesForecastYear1'!$E$14 | I44: =+I42*'3a-SalesForecastYear1'!$E$14 | J44: =+J42*'3a-SalesForecastYear1'!$E$14 | ... N44: =+N42*'3a-SalesForecastYear1'!$E$14 | O44: =SUM(C44:N44) | P44: =IF(O43=0,0,O44/O43) | Q44: =IF($O$48=0,0,O44/$O$48) | R44: =+R42*'3a-SalesForecastYear1'!$E$14 | S44: =+S42*'3a-SalesForecastYear1'!$E$14 | T44: =+T42*'3a-SalesForecastYear1'!$E$14 | U44: =+U42*'3a-SalesForecastYear1'!$E$14 | V44: =+V42*'3a-SalesForecastYear1'!$E$14 | W44: =+W42*'3a-SalesForecastYear1'!$E$14 | X44: =+X42*'3a-SalesForecastYear1'!$E$14 | Y44: =+Y42*'3a-SalesForecastYear1'!$E$14 | ... AC44: =+AC42*'3a-SalesForecastYear1'!$E$14 | AD44: =SUM(R44:AC44) | AE44: =IF(AD43=0,0,AD44/AD43) | AF44: =IF($AD$48=0,0,AD44/$AD$48)
A45: Margin | B45: ='3a-SalesForecastYear1'!O51 | C45: =C43-C44 | D45: =D43-D44 | E45: =E43-E44 | F45: =F43-F44 | G45: =G43-G44 | H45: =H43-H44 | I45: =I43-I44 | J45: =J43-J44 | ... N45: =N43-N44 | O45: =SUM(C45:N45) | P45: =IF(O43=0,0,O45/O43) | Q45: =IF($O$49=0,0,O45/$O$49) | R45: =R43-R44 | S45: =S43-S44 | T45: =T43-T44 | U45: =U43-U44 | V45: =V43-V44 | W45: =W43-W44 | X45: =X43-X44 | Y45: =Y43-Y44 | ... AC45: =AC43-AC44 | AD45: =SUM(R45:AC45) | AE45: =IF(AD43=0,0,AD45/AD43) | AF45: =IF($AD$49=0,0,AD45/$AD$49)
A46: Total Units Sold | B46: =Units_Annual_Total | C46: =C12+C18+C24+C30+C36+C42 | D46: =D12+D18+D24+D30+D36+D42 | E46: =E12+E18+E24+E30+E36+E42 | F46: =F12+F18+F24+F30+F36+F42 | G46: =G12+G18+G24+G30+G36+G42 | H46: =H12+H18+H24+H30+H36+H42 | I46: =I12+I18+I24+I30+I36+I42 | J46: =J12+J18+J24+J30+J36+J42 | ... N46: =N12+N18+N24+N30+N36+N42 | O46: =SUM(C46:N46) | R46: =R12+R18+R24+R30+R36+R42 | S46: =S12+S18+S24+S30+S36+S42 | T46: =T12+T18+T24+T30+T36+T42 | U46: =U12+U18+U24+U30+U36+U42 | V46: =V12+V18+V24+V30+V36+V42 | W46: =W12+W18+W24+W30+W36+W42 | X46: =X12+X18+X24+X30+X36+X42 | Y46: =Y12+Y18+Y24+Y30+Y36+Y42 | ... AC46: =AC12+AC18+AC24+AC30+AC36+AC42 | AD46: =SUM(R46:AC46)
A47: Total Sales | B47: =Sales_Annual_Total | C47: =C13+C19+C25+C31+C37+C43 | D47: =D13+D19+D25+D31+D37+D43 | E47: =E13+E19+E25+E31+E37+E43 | F47: =F13+F19+F25+F31+F37+F43 | G47: =G13+G19+G25+G31+G37+G43 | H47: =H13+H19+H25+H31+H37+H43 | I47: =I13+I19+I25+I31+I37+I43 | J47: =J13+J19+J25+J31+J37+J43 | ... N47: =N13+N19+N25+N31+N37+N43 | O47: =SUM(C47:N47) | R47: =R13+R19+R25+R31+R37+R43 | S47: =S13+S19+S25+S31+S37+S43 | T47: =T13+T19+T25+T31+T37+T43 | U47: =U13+U19+U25+U31+U37+U43 | V47: =V13+V19+V25+V31+V37+V43 | W47: =W13+W19+W25+W31+W37+W43 | X47: =X13+X19+X25+X31+X37+X43 | Y47: =Y13+Y19+Y25+Y31+Y37+Y43 | ... AC47: =AC13+AC19+AC25+AC31+AC37+AC43 | AD47: =SUM(R47:AC47)
A48: Total Cost of Goods Sold | B48: =COGS_Annual_Total | C48: =C14+C20+C26+C32+C38+C44 | D48: =D14+D20+D26+D32+D38+D44 | E48: =E14+E20+E26+E32+E38+E44 | F48: =F14+F20+F26+F32+F38+F44 | G48: =G14+G20+G26+G32+G38+G44 | H48: =H14+H20+H26+H32+H38+H44 | I48: =I14+I20+I26+I32+I38+I44 | J48: =J14+J20+J26+J32+J38+J44 | ... N48: =N14+N20+N26+N32+N38+N44 | O48: =SUM(C48:N48) | R48: =R14+R20+R26+R32+R38+R44 | S48: =S14+S20+S26+S32+S38+S44 | T48: =T14+T20+T26+T32+T38+T44 | U48: =U14+U20+U26+U32+U38+U44 | V48: =V14+V20+V26+V32+V38+V44 | W48: =W14+W20+W26+W32+W38+W44 | X48: =X14+X20+X26+X32+X38+X44 | Y48: =Y14+Y20+Y26+Y32+Y38+Y44 | ... AC48: =AC14+AC20+AC26+AC32+AC38+AC44 | AD48: =SUM(R48:AC48)
A49: Total Margin | B49: =Margin_Annual_Total | C49: =C47-C48 | D49: =D47-D48 | E49: =E47-E48 | F49: =F47-F48 | G49: =G47-G48 | H49: =H47-H48 | I49: =I47-I48 | J49: =J47-J48 | ... N49: =N47-N48 | O49: =O15+O21+O27+O33+O39+O45 | R49: =R47-R48 | S49: =S47-S48 | T49: =T47-T48 | U49: =U47-U48 | V49: =V47-V48 | W49: =W47-W48 | X49: =X47-X48 | Y49: =Y47-Y48 | ... AC49: =AC47-AC48 | AD49: =AD15+AD21+AD27+AD33+AD39+AD45

Sheet 4-AdditionalInputs
B2: Additional Inputs
B4: Prepared By: | C4: Company Name:
B5: =IF(ISBLANK(Directions!C10), "Owner", Directions!C10) | C5: =IF(ISBLANK(Directions!D10), "Company 1", Directions!D10)
B7: Accounts Receivable (A/R) Days Sales Outstanding
B8: Percent of Collections | C8: Year 1 | D8: Year 2 | E8: Year 3
B9: Paid within 30 days | C9: 1 | D9: 1 | E9: 1
B10: Paid between 30 and 60 days | C10: 0 | D10: 0 | E10: 0
B11: Paid in more than 60 days | C11: 0 | D11: 0 | E11: 0
B12: Allowance for bad debt | C12: =1-SUM(C9:C11) | D12: =1-SUM(D9:D11) | E12: =1-SUM(E9:E11)
B13: This should equal 100% ----> | C13: =SUM(C9:C12) | D13: =SUM(D9:D12) | E13: =SUM(E9:E12)
B15: Accounts Payable (A/P)
B16: Percent of Disbursements | C16: Year 1 | D16: Year 2 | E16: Year 3
B17: Paid within 30 days | C17: 1 | D17: 1 | E17: 1
B18: Paid between 30 and 60 days | C18: 0 | D18: 0 | E18: 0
B19: Paid in more than 60 days | C19: 0 | D19: 0 | E19: 0
B20: This should equal 100% ----> | C20: =SUM(C17:C19) | D20: =SUM(D17:D19) | E20: =SUM(E17:E19)
B23: Line of Credit Assumptions
B24: Desired Minimum Cash Balance | D24: 0
B25: Line of Credit Interest Rate | D25: 0.08
B27: Additional Fixed Assets Purchases
B28: Fixed Assets | C28: Depreciation (years) | D28: ='2a-PayrollYear1'!F7 | E28: ='2a-PayrollYear1'!G7 | F28: ='2a-PayrollYear1'!H7 | G28: ='2a-PayrollYear1'!I7 | H28: ='2a-PayrollYear1'!J7 | I28: ='2a-PayrollYear1'!K7 | J28: ='2a-PayrollYear1'!L7 | K28: ='2a-PayrollYear1'!M7 | ... O28: ='2a-PayrollYear1'!Q7 | P28: Year 1 Totals | Q28: Year 2 Total | R28: Year 3 Total
B29: Real Estate | C29: 20 | D29: =Buildings | P29: =SUM(D29:O29)
B30: Leasehold Improvements | C30: 7 | D30: =LeaseImprovements | P30: =SUM(D30:O30)
B31: Equipment | C31: 7 | D31: =Equipment | P31: =SUM(D31:O31)
B32: Furniture and Fixtures | C32: 5 | D32: =Furniture | P32: =SUM(D32:O32)
B33: Vehicles | C33: 5 | D33: =Vehicles | P33: =SUM(D33:O33)
B34: Other Fixed Assets | C34: 5 | D34: =OtherFixedAssets | P34: =SUM(D34:O34) | Q34: 0 | R34: 0
B35: Total Additional Fixed Assets | D35: =SUM(D29:D34) | E35: =SUM(E29:E34) | F35: =SUM(F29:F34) | G35: =SUM(G29:G34) | H35: =SUM(H29:H34) | I35: =SUM(I29:I34) | J35: =SUM(J29:J34) | K35: =SUM(K29:K34) | ... R35: =SUM(R29:R34)
B38: Income Tax Assumptions
B39: Effective Income Tax Rate - Year 1 | C39: 0
B40: Effective Income Tax Rate - Year 2 | C40: 0
B41: Effective Income Tax Rate - Year 3 | C41: 0
B43: Amortization of Start-Up Costs
B44: Amortization Period in Years | C44: 3

Sheet 5a-OpExYear1
B2: Operating Expenses Year 1
B4: Prepared By: | C4: Company Name:
B5: =IF(ISBLANK(Directions!C10), "Owner", Directions!C10) | C5: =IF(ISBLANK(Directions!D10), "Company 1", Directions!D10)
C8: ='2a-PayrollYear1'!F7 | D8: ='2a-PayrollYear1'!G7 | E8: ='2a-PayrollYear1'!H7 | F8: ='2a-PayrollYear1'!I7 | G8: ='2a-PayrollYear1'!J7 | H8: ='2a-PayrollYear1'!K7 | I8: ='2a-PayrollYear1'!L7 | J8: ='2a-PayrollYear1'!M7 | ... N8: ='2a-PayrollYear1'!Q7 | O8: Annual Totals
B9: Expenses
B10: Advertising | O10: =SUM(C10:N10)
B11: Car and Truck Expenses | O11: =SUM(C11:N11)
B12: Commissions and Fees | O12: =SUM(C12:N12)
B13: Contract Labor (Not included in payroll) | C13: 66.67 | D13: 66.67 | E13: 66.67 | F13: 66.67 | G13: 66.67 | H13: 66.67 | I13: 66.67 | J13: 66.67 | K13: 66.67 | L13: 66.67 | M13: 66.67 | N13: 66.67 | O13: =SUM(C13:N13)
B14: Insurance (other than health) | O14: =SUM(C14:N14)
B15: Legal and Professional Services | O15: =SUM(C15:N15)
B16: Licenses | O16: =SUM(C16:N16)
B17: Office Expense | C17: 100 | D17: 100 | E17: 100 | F17: 100 | G17: 100 | H17: 100 | I17: 100 | J17: 100 | K17: 100 | L17: 100 | M17: 100 | N17: 100 | O17: =SUM(C17:N17)
B18: Rent or Lease -- Vehicles, Machinery, Equipment | O18: =SUM(C18:N18)
B19: Rent or Lease -- Other Business Property | O19: =SUM(C19:N19)
B20: Repairs and Maintenance | O20: =SUM(C20:N20)
B21: Supplies | O21: =SUM(C21:N21)
B22: Travel, Meals and Entertainment | O22: =SUM(C22:N22)
B23: Utilities | C23: In-Kind Prof Services: $81,000/yr (SDVOSB) | O23: =SUM(C23:N23)
B24: Miscellaneous | O24: =SUM(C24:N24)
B25: Total Expenses | C25: =SUM(C10:C24) | D25: =SUM(D10:D24) | E25: =SUM(E10:E24) | F25: =SUM(F10:F24) | G25: =SUM(G10:G24) | H25: =SUM(H10:H24) | I25: =SUM(I10:I24) | J25: =SUM(J10:J24) | ... N25: =SUM(N10:N24) | O25: =SUM(C25:N25)
B27: Other Expenses
B28: Depreciation | C28: ='Amortization&Depreciation'!C119 | D28: ='Amortization&Depreciation'!D119 | E28: ='Amortization&Depreciation'!E119 | F28: ='Amortization&Depreciation'!F119 | G28: ='Amortization&Depreciation'!G119 | H28: ='Amortization&Depreciation'!H119 | I28: ='Amortization&Depreciation'!I119 | J28: ='Amortization&Depreciation'!J119 | ... N28: ='Amortization&Depreciation'!N119 | O28: =SUM(C28:N28)
B29: Interest
B30: ='1-StartingPoint'!B37 | C30: ='Amortization&Depreciation'!C15 | D30: ='Amortization&Depreciation'!D15 | E30: ='Amortization&Depreciation'!E15 | F30: ='Amortization&Depreciation'!F15 | G30: ='Amortization&Depreciation'!G15 | H30: ='Amortization&Depreciation'!H15 | I30: ='Amortization&Depreciation'!I15 | J30: ='Amortization&Depreciation'!J15 | ... N30: ='Amortization&Depreciation'!N15 | O30: =SUM(C30:N30)
B31: ='1-StartingPoint'!B38 | C31: ='Amortization&Depreciation'!C35 | D31: ='Amortization&Depreciation'!D35 | E31: ='Amortization&Depreciation'!E35 | F31: ='Amortization&Depreciation'!F35 | G31: ='Amortization&Depreciation'!G35 | H31: ='Amortization&Depreciation'!H35 | I31: ='Amortization&Depreciation'!I35 | J31: ='Amortization&Depreciation'!J35 | ... N31: ='Amortization&Depreciation'!N35 | O31: =SUM(C31:N31)
B32: ='1-StartingPoint'!B39 | C32: ='Amortization&Depreciation'!C55 | D32: ='Amortization&Depreciation'!D55 | E32: ='Amortization&Depreciation'!E55 | F32: ='Amortization&Depreciation'!F55 | G32: ='Amortization&Depreciation'!G55 | H32: ='Amortization&Depreciation'!H55 | I32: ='Amortization&Depreciation'!I55 | J32: ='Amortization&Depreciation'!J55 | ... N32: ='Amortization&Depreciation'!N55 | O32: =SUM(C32:N32)
B33: ='1-StartingPoint'!B40 | C33: ='Amortization&Depreciation'!C75 | D33: ='Amortization&Depreciation'!D75 | E33: ='Amortization&Depreciation'!E75 | F33: ='Amortization&Depreciation'!F75 | G33: ='Amortization&Depreciation'!G75 | H33: ='Amortization&Depreciation'!H75 | I33: ='Amortization&Depreciation'!I75 | J33: ='Amortization&Depreciation'!J75 | ... N33: ='Amortization&Depreciation'!N75 | O33: =SUM(C33:N33)
B34: ='1-StartingPoint'!B41 | C34: ='Amortization&Depreciation'!C95 | D34: ='Amortization&Depreciation'!D95 | E34: ='Amortization&Depreciation'!E95 | F34: ='Amortization&Depreciation'!F95 | G34: ='Amortization&Depreciation'!G95 | H34: ='Amortization&Depreciation'!H95 | I34: ='Amortization&Depreciation'!I95 | J34: ='Amortization&Depreciation'!J95 | ... N34: ='Amortization&Depreciation'!N95 | O34: =SUM(C34:N34)
B35: Line of Credit | C35: ='6a-CashFlowYear1'!C26 | D35: ='6a-CashFlowYear1'!D26 | E35: ='6a-CashFlowYear1'!E26 | F35: ='6a-CashFlowYear1'!F26 | G35: ='6a-CashFlowYear1'!G26 | H35: ='6a-CashFlowYear1'!H26 | I35: ='6a-CashFlowYear1'!I26 | J35: ='6a-CashFlowYear1'!J26 | ... N35: ='6a-CashFlowYear1'!N26 | O35: =SUM(C35:N35)
B36: Bad Debt Expense | C36: =+'7a-IncomeStatementYear1'!C56 | D36: =+'7a-IncomeStatementYear1'!D56 | E36: =+'7a-IncomeStatementYear1'!E56 | F36: =+'7a-IncomeStatementYear1'!F56 | G36: =+'7a-IncomeStatementYear1'!G56 | H36: =+'7a-IncomeStatementYear1'!H56 | I36: =+'7a-IncomeStatementYear1'!I56 | J36: =+'7a-IncomeStatementYear1'!J56 | ... N36: =+'7a-IncomeStatementYear1'!N56 | O36: =SUM(C36:N36)
B37: Total Other Expenses | C37: =SUM(C28:C36) | D37: =SUM(D28:D36) | E37: =SUM(E28:E36) | F37: =SUM(F28:F36) | G37: =SUM(G28:G36) | H37: =SUM(H28:H36) | I37: =SUM(I28:I36) | J37: =SUM(J28:J36) | ... N37: =SUM(N28:N36) | O37: =SUM(C37:N37)
B38: Total Fixed Operating Expenses | C38: =C25+C37 | D38: =D25+D37 | E38: =E25+E37 | F38: =F25+F37 | G38: =G25+G37 | H38: =H25+H37 | I38: =I25+I37 | J38: =J25+J37 | ... N38: =N25+N37 | O38: =SUM(C38:N38)

Sheet 5b-OpExYrs1-3
B2: Operating Expenses Years 1-3
B4: Prepared By: | C4: Company Name:
B5: =IF(ISBLANK(Directions!C10), "Owner", Directions!C10) | C5: =IF(ISBLANK(Directions!D10), "Company 1", Directions!D10)
B7: Line Item | C7: =IF(Directions!F10>0,Directions!F10,"First Year") | D7: Growth Rate 1 to 2 | E7: =IF(Directions!F10>0,Directions!F10+1,"Second Year") | F7: Growth Rate 2 to 3 | G7: =IF(Directions!F10>0,Directions!F10+2,"Third Year")
B8: ='5a-OpExYear1'!B10 | C8: ='5a-OpExYear1'!O10 | D8: 0.03 | E8: =C8*(1+D8) | F8: 0.03 | G8: =E8*(1+F8)
B9: ='5a-OpExYear1'!B11 | C9: ='5a-OpExYear1'!O11 | D9: 0.03 | E9: =C9*(1+D9) | F9: 0.03 | G9: =E9*(1+F9)
B10: ='5a-OpExYear1'!B12 | C10: ='5a-OpExYear1'!O12 | D10: 0.05 | E10: =C10*(1+D10) | F10: 0.05 | G10: =E10*(1+F10)
B11: ='5a-OpExYear1'!B13 | C11: ='5a-OpExYear1'!O13 | D11: 0.03 | E11: =C11*(1+D11) | F11: 0.03 | G11: =E11*(1+F11)
B12: ='5a-OpExYear1'!B14 | C12: ='5a-OpExYear1'!O14 | D12: 0.03 | E12: =C12*(1+D12) | F12: 0.03 | G12: =E12*(1+F12)
B13: ='5a-OpExYear1'!B15 | C13: ='5a-OpExYear1'!O15 | D13: 0.03 | E13: =C13*(1+D13) | F13: 0.03 | G13: =E13*(1+F13)
B14: ='5a-OpExYear1'!B16 | C14: ='5a-OpExYear1'!O16 | D14: 0.05 | E14: =C14*(1+D14) | F14: 0.05 | G14: =E14*(1+F14)
B15: ='5a-OpExYear1'!B17 | C15: ='5a-OpExYear1'!O17 | D15: 0.03 | E15: =C15*(1+D15) | F15: 0.03 | G15: =E15*(1+F15)
B16: ='5a-OpExYear1'!B18 | C16: ='5a-OpExYear1'!O18 | D16: 0.03 | E16: =C16*(1+D16) | F16: 0.03 | G16: =E16*(1+F16)
B17: ='5a-OpExYear1'!B19 | C17: ='5a-OpExYear1'!O19 | D17: 0.03 | E17: =C17*(1+D17) | F17: 0.03 | G17: =E17*(1+F17)
B18: ='5a-OpExYear1'!B20 | C18: ='5a-OpExYear1'!O20 | D18: 0.05 | E18: =C18*(1+D18) | F18: 0.05 | G18: =E18*(1+F18)
B19: ='5a-OpExYear1'!B21 | C19: ='5a-OpExYear1'!O21 | D19: 0.03 | E19: =C19*(1+D19) | F19: 0.03 | G19: =E19*(1+F19)
... B22: ='5a-OpExYear1'!B24 | C22: ='5a-OpExYear1'!O24 | D22: 0.03 | E22: =C22*(1+D22) | F22: 0.03 | G22: =E22*(1+F22)
B23: Total Expenses | C23: =SUM(C8:C22) | E23: =SUM(E8:E22) | G23: =SUM(G8:G22)
B25: Other Expenses
B26: Depreciation | C26: ='5a-OpExYear1'!O28 | E26: ='Amortization&Depreciation'!O123 | G26: ='Amortization&Depreciation'!O127
B27: Interest
B28: ='1-StartingPoint'!B37 | C28: ='5a-OpExYear1'!O30 | E28: =IF('1-StartingPoint'!$F37<36, 0, 'Amortization&Depreciation'!O19) | G28: =IF('1-StartingPoint'!$F37<36, 0, 'Amortization&Depreciation'!O23)
B29: ='1-StartingPoint'!B38 | C29: ='5a-OpExYear1'!O31 | E29: =IF('1-StartingPoint'!$F38<36, 0, 'Amortization&Depreciation'!O39) | G29: =IF('1-StartingPoint'!$F38<36, 0, 'Amortization&Depreciation'!O43)
B30: ='1-StartingPoint'!B39 | C30: ='5a-OpExYear1'!O32 | E30: =IF('1-StartingPoint'!$F39<36, 0, 'Amortization&Depreciation'!O59) | G30: =IF('1-StartingPoint'!$F39<36, 0, 'Amortization&Depreciation'!O63)
B31: ='1-StartingPoint'!B40 | C31: ='5a-OpExYear1'!O33 | E31: =IF('1-StartingPoint'!$F40<36, 0, 'Amortization&Depreciation'!O79) | G31: =IF('1-StartingPoint'!$F40<36, 0, 'Amortization&Depreciation'!O83)
B32: ='1-StartingPoint'!B41 | C32: ='5a-OpExYear1'!O34 | E32: =IF('1-StartingPoint'!$F41<36, 0, 'Amortization&Depreciation'!O99) | G32: =IF('1-StartingPoint'!$F41<36, 0, 'Amortization&Depreciation'!O103)
B33: Line of Credit | C33: =+'6a-CashFlowYear1'!O26 | E33: =+'6b-CashFlowYrs1-3'!O25 | G33: ='6b-CashFlowYrs1-3'!AB25
B34: Bad Debt Expense | C34: =+'5a-OpExYear1'!O36
B35: Total Other Expenses | C35: =SUM(C26:C34) | E35: =SUM(E26:E34) | G35: =SUM(G26:G34)
B36: Total Operating Expenses | C36: =SUM(C8:C22)+C35 | E36: =SUM(E8:E22)+E35 | G36: =SUM(G8:G22)+G35

Sheet 6a-CashFlowYear1
B2: Cash Flow Forecast Year 1
B4: Prepared By: | C4: Company Name:
B5: =IF(ISBLANK(Directions!C10), "Owner", Directions!C10) | C5: =IF(ISBLANK(Directions!D10), "Company 1", Directions!D10)
C7: ='3a-SalesForecastYear1'!C16 | D7: ='3a-SalesForecastYear1'!D16 | E7: ='3a-SalesForecastYear1'!E16 | F7: ='3a-SalesForecastYear1'!F16 | G7: ='3a-SalesForecastYear1'!G16 | H7: ='3a-SalesForecastYear1'!H16 | I7: ='3a-SalesForecastYear1'!I16 | J7: ='3a-SalesForecastYear1'!J16 | ... N7: ='3a-SalesForecastYear1'!N16 | O7: Totals
B8: Beginning Balance | C8: =Working_Capital | D8: =C33 | E8: =D33 | F8: =E33 | G8: =F33 | H8: =G33 | I8: =H33 | J8: =I33 | K8: =J33 | ... N8: =M33
B9: Cash Inflows
B10: Cash Sales | C10: ='3a-SalesForecastYear1'!C53*'4-AdditionalInputs'!$C$9 | D10: ='3a-SalesForecastYear1'!D53*'4-AdditionalInputs'!$C$9 | E10: ='3a-SalesForecastYear1'!E53*'4-AdditionalInputs'!$C$9 | F10: ='3a-SalesForecastYear1'!F53*'4-AdditionalInputs'!$C$9 | G10: ='3a-SalesForecastYear1'!G53*'4-AdditionalInputs'!$C$9 | H10: ='3a-SalesForecastYear1'!H53*'4-AdditionalInputs'!$C$9 | I10: ='3a-SalesForecastYear1'!I53*'4-AdditionalInputs'!$C$9 | J10: ='3a-SalesForecastYear1'!J53*'4-AdditionalInputs'!$C$9 | ... N10: ='3a-SalesForecastYear1'!N53*'4-AdditionalInputs'!$C$9 | O10: =SUM(C10:N10)
B11: Accounts Receivable | C11: 0 | D11: =('3a-SalesForecastYear1'!C53*'4-AdditionalInputs'!$C$10) | E11: =('3a-SalesForecastYear1'!D53*'4-AdditionalInputs'!$C$10)+('3a-SalesForecastYear1'!C53*'4-AdditionalInputs'!$C$11) | F11: =('3a-SalesForecastYear1'!E53*'4-AdditionalInputs'!$C$10)+('3a-SalesForecastYear1'!D53*'4-AdditionalInputs'!$C$11) | G11: =('3a-SalesForecastYear1'!F53*'4-AdditionalInputs'!$C$10)+('3a-SalesForecastYear1'!E53*'4-AdditionalInputs'!$C$11) | H11: =('3a-SalesForecastYear1'!G53*'4-AdditionalInputs'!$C$10)+('3a-SalesForecastYear1'!F53*'4-AdditionalInputs'!$C$11) | I11: =('3a-SalesForecastYear1'!H53*'4-AdditionalInputs'!$C$10)+('3a-SalesForecastYear1'!G53*'4-AdditionalInputs'!$C$11) | J11: =('3a-SalesForecastYear1'!I53*'4-AdditionalInputs'!$C$10)+('3a-SalesForecastYear1'!H53*'4-AdditionalInputs'!$C$11) | K11: =('3a-SalesForecastYear1'!J53*'4-AdditionalInputs'!$C$10)+('3a-SalesForecastYear1'!I53*'4-AdditionalInputs'!$C$11) | L11: =('3a-SalesForecastYear1'!K53*'4-AdditionalInputs'!$C$10)+('3a-SalesForecastYear1'!J53*'4-AdditionalInputs'!$C$11) | ... N11: =('3a-SalesForecastYear1'!M53*'4-AdditionalInputs'!$C$10)+('3a-SalesForecastYear1'!L53*'4-AdditionalInputs'!$C$11) | O11: =SUM(C11:N11)
B12: Total Cash Inflows | C12: =SUM(C10:C11) | D12: =SUM(D10:D11) | E12: =SUM(E10:E11) | F12: =SUM(F10:F11) | G12: =SUM(G10:G11) | H12: =SUM(H10:H11) | I12: =SUM(I10:I11) | J12: =SUM(J10:J11) | ... O12: =SUM(O10:O11)
B14: Cash Outflows
B15: Investing Activities
B16: New Fixed Asset Purchases | C16: 0 | D16: ='4-AdditionalInputs'!E35 | E16: ='4-AdditionalInputs'!F35 | F16: ='4-AdditionalInputs'!G35 | G16: ='4-AdditionalInputs'!H35 | H16: ='4-AdditionalInputs'!I35 | I16: ='4-AdditionalInputs'!J35 | J16: ='4-AdditionalInputs'!K35 | K16: ='4-AdditionalInputs'!L35 | ... N16: ='4-AdditionalInputs'!O35 | O16: =SUM(C16:N16)
B17: Additional Inventory | O17: =SUM(C17:N17)
